Workbook

Sheet Como Utilizar
B4: Em todas as abas da Planilha de Medição de Obras, preencha apenas os campos com fundo azul claro. Todos as outras informações são geradas automaticamente.

Sheet Cadastro Institucional
B3: Fatores de Cálculo | C3: BDI
C4: LS (Encargos Sociais) | D4: 0 | F4: Preencha apenas as células com esse azul claro como cor de fundo!
B6: Obra | C6: Nome | D6: Condominio Palatium
C7: Endereço
B9: Informações Institucionais | C9: Razão Social | D9: F A Alves Vasoncelos Ltda.
C10: CNPJ | D10: 23.471.824/0001-45
C11: Inscrição Estadual
C12: Responsável | D12: Francisco de Assis Alves Vasocnelos
C13: Cargo | D13: Enegenheiro Responsável
C14: Telefone | D14: (88) 9 8802-1038
C15: E-mail | D15: spateeng@gmail.com

Sheet Etapas
E1: OBRA | F1: ='Cadastro Institucional'!D$6 -> Condominio Palatium | G1: ='Cadastro Institucional'!D$7 -> 0
A2: CNPJ | B2: Razão Social | C2: Inscrição Estadual | D2: Responsável | E2: Cargo | F2: Telefone | G2: E-mail
A3: ='Cadastro Institucional'!D$10 -> 23.471.824/0001-45 | B3: ='Cadastro Institucional'!D$9 -> F A Alves Vasoncelos Ltda. | C3: ='Cadastro Institucional'!D$11 -> 0 | D3: ='Cadastro Institucional'!D$12 -> Francisco de Assis Alves Vasocnelos | E3: ='Cadastro Institucional'!D$13 -> Enegenheiro Responsável | F3: ='Cadastro Institucional'!D$14 -> (88) 9 8802-1038 | G3: ='Cadastro Institucional'!D$15 -> spateeng@gmail.com
A5: Etapa | B5: Descrição
A6: 1.1 | B6: Instalações Elétricas - Tubulações Laje aparente | D6: Preencha apenas as células com esse azul claro como cor de fundo!
A7: 1.2 | B7: Instalações Elétricas - Tubulações Piso e paredes
A8: 1.3 | B8: Instalações Elétricas - Fiação de Distribuição
A9: 1.4 | B9: Instalações Elétricas - Tomadas e Interruptores
A10: 1.5 | B10: Instalações Elétricas - Luminárias e Acessórios (Somente Mão de Obra)
A11: 1.6 | B11: Instalações Elétricas - Eletrocalhas e Acessórios
A12: 1.7 | B12: Instalações Elétricas - Quadros - Infraestrutura
A13: 1.8 | B13: Instalações Elétricas - Quadros - Cabeamento
A14: 1.9 | B14: Instalações Elétricas - Quadros
A15: 2.1 | B15: Instalações de Telecom/Infra CFTV - Tubulações Laje aparente e paredes
A16: 2.2 | B16: Instalações de Telecom/Infra CFTV - Tomadas e afins
A17: 2.3 | B17: Instalações de Telecom/Infra CFTV - Fiação de distribuição
A18: 2.4 | B18: Instalações de Telecom/Infra CFTV - Alimentadores dos Quadros
... A47: 7.7 | B47: Sistema de Climatização - Lazer - 01 AC 60000 BTU/h
A48: 41
A49: 42
A50: 43
A51: 44
A52: 45

Sheet Itens de Contrato
E1: OBRA | F1: ='Cadastro Institucional'!D$6 -> Condominio Palatium | J1: ='Cadastro Institucional'!D$7 -> 0
A2: CNPJ | B2: Razão Social | C2: Inscrição Estadual | D2: Responsável | E2: Cargo | F2: Telefone | I2: E-mail
A3: ='Cadastro Institucional'!D$10 -> 23.471.824/0001-45 | B3: ='Cadastro Institucional'!D$9 -> F A Alves Vasoncelos Ltda. | C3: ='Cadastro Institucional'!D$11 -> 0 | D3: ='Cadastro Institucional'!D$12 -> Francisco de Assis Alves Vasocnelos | E3: ='Cadastro Institucional'!D$13 -> Enegenheiro Responsável | F3: ='Cadastro Institucional'!D$14 -> (88) 9 8802-1038 | I3: ='Cadastro Institucional'!D$15 -> spateeng@gmail.com
L4: Preencha apenas as células com esse azul claro como cor de fundo!
A5: Etapa | B5: Item | C5: Descrição | D5: Unidade | E5: Quantidade | F5: Valor Unitário Material | G5: Valor Unitário Mão de Obra | H5: Valor Total Material | I5: Valor Total Mão de obra | J5: Valor Total (Com BDI e Leis Sociais)
A6: Instalações Elétricas - Tubulações Laje aparente | B6: 1.1.1 | C6: ELETRODUTO PVC RÍGIDO ROSCÁVEL, CLASSE B, NBR-15465, Ф 3/4" x 3,0m, FAB.TIGRE, AMANCO | D6: VR | E6: 1907 | F6: 21.977485 | G6: 15.384239 | H6: =F6*E6 -> 41911.064 | I6: =(E6*F6)*0.65 -> 27242.191 | J6: =(E6*(F6+G6)*(1+(SUM('Cadastro Institucional'!D$3:D$4)))) -> 71248.808
A7: Instalações Elétricas - Tubulações Laje aparente | B7: 1.1.2 | C7: ELETRODUTO PVC RÍGIDO ROSCÁVEL, CLASSE B, NBR-15465, Ф 1" x 3,0m, FAB.TIGRE, AMANCO | D7: VR | E7: 31 | F7: 35.029185 | G7: 24.520429 | H7: =F7*E7 -> 1085.9047 | I7: =(E7*F7)*0.65 -> 705.83808 | J7: =(E7*(F7+G7)*(1+(SUM('Cadastro Institucional'!D$3:D$4)))) -> 1846.038
A8: Instalações Elétricas - Tubulações Laje aparente | B8: 1.1.3 | C8: CURVA 90o P/ELETRODUTO PVC RÍGIDO, ROSCA Ф 3/4", FAB.TIGRE, AMANCO | D8: UN | E8: 1653 | F8: 4.9806865 | G8: 3.4864806 | H8: =F8*E8 -> 8233.0749 | I8: =(E8*F8)*0.65 -> 5351.4987 | J8: =(E8*(F8+G8)*(1+(SUM('Cadastro Institucional'!D$3:D$4)))) -> 13996.227
A9: Instalações Elétricas - Tubulações Laje aparente | B9: 1.1.4 | C9: CURVA 90o P/ELETRODUTO PVC RÍGIDO, ROSCA Ф 1", FAB.TIGRE, AMANCO | D9: UN | E9: 3 | F9: 7.1011768 | G9: 4.9708238 | H9: =F9*E9 -> 21.303531 | I9: =(E9*F9)*0.65 -> 13.847295 | J9: =(E9*(F9+G9)*(1+(SUM('Cadastro Institucional'!D$3:D$4)))) -> 36.216002
A10: Instalações Elétricas - Tubulações Laje aparente | B10: 1.1.5 | C10: LUVA P/ELETRODUTO PVC RÍGIDO, ROSCA Ф 3/4", FAB.TIGRE, AMANCO | D10: UN | E10: 3560 | F10: 2.6465034 | G10: 1.8525524 | H10: =F10*E10 -> 9421.5521 | I10: =(E10*F10)*0.65 -> 6124.0089 | J10: =(E10*(F10+G10)*(1+(SUM('Cadastro Institucional'!D$3:D$4)))) -> 16016.639
A11: Instalações Elétricas - Tubulações Laje aparente | B11: 1.1.6 | C11: LUVA P/ELETRODUTO PVC RÍGIDO, ROSCA Ф 1", FAB.TIGRE, AMANCO | D11: UN | E11: 34 | F11: 4.2574185 | G11: 2.980193 | H11: =F11*E11 -> 144.75223 | I11: =(E11*F11)*0.65 -> 94.088949 | J11: =(E11*(F11+G11)*(1+(SUM('Cadastro Institucional'!D$3:D$4)))) -> 246.07879
A12: Instalações Elétricas - Tubulações Laje aparente | B12: 1.1.7 | C12: BUCHA E ARRUELA EM LIGA DE ALUMINIO SILÍCIO Ф 3/4", FAB. WETZEL, TRAMONTINA | D12: PA | E12: 2914 | F12: 3.5834642 | G12: 2.508425 | H12: =F12*E12 -> 10442.215 | I12: =(E12*F12)*0.65 -> 6787.4396 | J12: =(E12*(F12+G12)*(1+(SUM('Cadastro Institucional'!D$3:D$4)))) -> 17751.765
A13: Instalações Elétricas - Tubulações Laje aparente | B13: 1.1.8 | C13: ARAME GALVANIZADO BITOLA 16BWG - GERDAU | D13: KG | E13: 55 | F13: 42.574185 | G13: 29.80193 | H13: =F13*E13 -> 2341.5802 | I13: =(E13*F13)*0.65 -> 1522.0271 | J13: =(E13*(F13+G13)*(1+(SUM('Cadastro Institucional'!D$3:D$4)))) -> 3980.6863
A14: Instalações Elétricas - Tubulações Laje aparente | B14: 1.1.9 | C14: PARAFUSO FENDA, ROSCA SOBERBA C/BUCHA DE NYLON Ref. S8 x 40mm, FAB. MAXTIL,CARMEHIL | D14: UN | E14: 3829 | F14: 1.4300981 | G14: 1.0010687 | H14: =F14*E14 -> 5475.8457 | I14: =(E14*F14)*0.65 -> 3559.2997 | J14: =(E14*(F14+G14)*(1+(SUM('Cadastro Institucional'!D$3:D$4)))) -> 9308.9377
A15: Instalações Elétricas - Tubulações Laje aparente | B15: 1.1.10 | C15: ABRAÇADEIRA AÇO GALVANIZADO, TIPO "D" C/CUNHA Ф 3/4", Ref. MAX.AA.TDC, FAB. MAXTIL,CARMEHIL | D15: UN | E15: 2922 | F15: 1.3643465 | G15: 0.95504253 | H15: =F15*E15 -> 3986.6204 | I15: =(E15*F15)*0.65 -> 2591.3033 | J15: =(E15*(F15+G15)*(1+(SUM('Cadastro Institucional'!D$3:D$4)))) -> 6777.2547
A16: Instalações Elétricas - Tubulações Laje aparente | B16: 1.1.11 | C16: CONDULETE MÚLTIPLO EM LIGA DE ALUMÍNIO, PARAF. AÇO ZINCADO, TAMPA E JUNTA DE VEDAÇÃO, ROSCA Ф 3/4", FAB. WETZEL | D16: UN | E16: 68 | F16: 22.930884 | G16: 16.051619 | H16: =F16*E16 -> 1559.3001 | I16: =(E16*F16)*0.65 -> 1013.5451 | J16: =(E16*(F16+G16)*(1+(SUM('Cadastro Institucional'!D$3:D$4)))) -> 2650.8101
A17: Instalações Elétricas - Tubulações Laje aparente | B17: 1.1.12 | C17: CONECTOR EM ALUM.SILICIO P/CONDULETE MÚLTIPLO, PARAF. AÇO ZINCADO, ROSCA EXTERNA Ф 3/4", FAB. WETZEL | D17: UN | E17: 204 | F17: 1.9232354 | G17: 1.3462648 | H17: =F17*E17 -> 392.34002 | I17: =(E17*F17)*0.65 -> 255.02101 | J17: =(E17*(F17+G17)*(1+(SUM('Cadastro Institucional'!D$3:D$4)))) -> 666.97804
... A58: Instalações Elétricas - Tomadas e Interruptores | B58: 1.4.20 | C58: SENSOR DE PRESENÇA FIXO PASSIVO THREE-WAY ALCANCE MINIMO DE 10,00m 180° X 12m EM CAIXA 4x2 - SPP0TR EXATRON | D58: UN | E58: 17 | F58: 79.72386 | G58: 55.806702 | H58: =F58*E58 -> 1355.3056 | I58: =(E58*F58)*0.65 -> 880.94866 | J58: =(E58*(F58+G58)*(1+(SUM('Cadastro Institucional'!D$3:D$4)))) -> 2304.0196
A59: Instalações Elétricas - Luminárias e Acessórios (Somente Mão de Obra) | B59: 1.5.1 | C59: LUMINARIA SLIM QUADRADA, EMBUTIDA NO FORRO, CORPO E REFLETOR EM ALUM., C/PROTEÇÃO EM VIDRO JATEADO | D59: UN | E59: 89 | G59: 13.77 | H59: 0 | I59: =(E59*G59) -> 1225.53 | J59: =(E59*(F59+G59)*(1+(SUM('Cadastro Institucional'!D$3:D$4)))) -> 1225.53
A60: Instalações Elétricas - Luminárias e Acessórios (Somente Mão de Obra) | B60: 1.5.2 | C60: LUMINARIA CIRCULAR, EMBUTIDA NO FORRO, CORPO E REFLETOR EM ALUM., C/PROTEÇÃO EM VIDRO TEMPERADO - A DEFINIR - VARANDAS | D60: UN | E60: 78 | G60: 13.77 | H60: 0 | I60: =(E60*G60) -> 1074.06 | J60: =(E60*(F60+G60)*(1+(SUM('Cadastro Institucional'!D$3:D$4)))) -> 1074.06
A61: Instalações Elétricas - Luminárias e Acessórios (Somente Mão de Obra) | B61: 1.5.3 | C61: ARANDELA NAVAL TIPO TARTARUGA EM ALUMINIO FUNDIDO C/VIDRO E GRADE, COM LÂMPADA LED 12W - PAREDE/TETO | D61: UN | E61: 15 | G61: 25.17 | H61: 0 | I61: =(E61*G61) -> 377.55 | J61: =(E61*(F61+G61)*(1+(SUM('Cadastro Institucional'!D$3:D$4)))) -> 377.55
A62: Instalações Elétricas - Luminárias e Acessórios (Somente Mão de Obra) | B62: 1.5.4 | C62: LUMINÁRIA SOBREPOR REDONDA COR BRANCA C/FECHAMENTO EM VIDRO JATEADO | D62: UN | E62: 4 | G62: 13.77 | H62: 0 | I62: =(E62*G62) -> 55.08 | J62: =(E62*(F62+G62)*(1+(SUM('Cadastro Institucional'!D$3:D$4)))) -> 55.08
A63: Instalações Elétricas - Luminárias e Acessórios (Somente Mão de Obra) | B63: 1.5.5 | C63: LUMINÁRIA EMBUTIR COR BRANCA C/MINI DICRÓICA | D63: UN | E63: 7 | G63: 13.77 | H63: 0 | I63: =(E63*G63) -> 96.39 | J63: =(E63*(F63+G63)*(1+(SUM('Cadastro Institucional'!D$3:D$4)))) -> 96.39
A64: Instalações Elétricas - Luminárias e Acessórios (Somente Mão de Obra) | B64: 1.5.6 | C64: LUMINÁRIA EMBUTIR ORIENTÁVEL COR BRANCA C/MINI DICRÓICA | D64: UN | E64: 4 | G64: 14.9 | H64: 0 | I64: =(E64*G64) -> 59.6 | J64: =(E64*(F64+G64)*(1+(SUM('Cadastro Institucional'!D$3:D$4)))) -> 59.6
A65: Instalações Elétricas - Luminárias e Acessórios (Somente Mão de Obra) | B65: 1.5.7 | C65: LUMINÁRIA DE EMBUTIR COR BRANCA C/LÂMPADA PAR-20 | D65: UN | E65: 10 | G65: 13.77 | H65: 0 | I65: =(E65*G65) -> 137.7 | J65: =(E65*(F65+G65)*(1+(SUM('Cadastro Institucional'!D$3:D$4)))) -> 137.7
A66: Instalações Elétricas - Luminárias e Acessórios (Somente Mão de Obra) | B66: 1.5.8 | C66: ARANDELA DE SOBREPOR NA PAREDE C/LÂMPADA ELETRÔNICA | D66: UN | E66: 5 | G66: 22.5 | H66: 0 | I66: =(E66*G66) -> 112.5 | J66: =(E66*(F66+G66)*(1+(SUM('Cadastro Institucional'!D$3:D$4)))) -> 112.5
A67: Instalações Elétricas - Luminárias e Acessórios (Somente Mão de Obra) | B67: 1.5.9 | C67: BALIZADOR EMBUTIDO NA ALVENARIA, USO EXTERNO, COM LÂMPADA LED 6W 3000K - MURETAS | D67: UN | E67: 20 | G67: 22.5 | H67: 0 | I67: =(E67*G67) -> 450 | J67: =(E67*(F67+G67)*(1+(SUM('Cadastro Institucional'!D$3:D$4)))) -> 450
A68: Instalações Elétricas - Luminárias e Acessórios (Somente Mão de Obra) | B68: 1.5.10 | C68: LUMINÁRIA EMBUTIR COR BRANCA C/LÂMPADA AR-70 | D68: UN | E68: 3 | G68: 22.5 | H68: 0 | I68: =(E68*G68) -> 67.5 | J68: =(E68*(F68+G68)*(1+(SUM('Cadastro Institucional'!D$3:D$4)))) -> 67.5
A69: Instalações Elétricas - Luminárias e Acessórios (Somente Mão de Obra) | B69: 1.5.11 | C69: LUMINÁRIA SUBAQUÁTICA COR BRANCA COM LED | D69: UN | E69: 8 | G69: 39.5 | H69: 0 | I69: =(E69*G69) -> 316 | J69: =(E69*(F69+G69)*(1+(SUM('Cadastro Institucional'!D$3:D$4)))) -> 316
A70: Instalações Elétricas - Luminárias e Acessórios (Somente Mão de Obra) | B70: 1.5.12 | C70: LUMINÁRIA BLINDADA DE EMBUTIR NO PISO | D70: UN | E70: 10 | G70: 45 | H70: 0 | I70: =(E70*G70) -> 450 | J70: =(E70*(F70+G70)*(1+(SUM('Cadastro Institucional'!D$3:D$4)))) -> 450
... A78: Instalações Elétricas - Luminárias e Acessórios (Somente Mão de Obra) | B78: 1.5.20 | C78: LUMINÁRIA DE OBSTÁCULO C/MASTRO, FOTO-CÉLULA MOD. ASE-1 E LÂMPADA LED 1x9W | D78: UN | E78: 1 | G78: 50.1 | H78: 0 | I78: =(E78*G78) -> 50.1 | J78: =(E78*(F78+G78)*(1+(SUM('Cadastro Institucional'!D$3:D$4)))) -> 50.1
A79: Instalações Elétricas - Eletrocalhas e Acessórios | B79: 1.6.1 | C79: ELETROCALHA C/VIROLA "C" EM CHAPA DE AÇO PERFURADA, CH#18 MSG, Ref.: MAX.ELC-GE, NBR-10476, DIM.300x100mm, FAB. MAXTIL,CARMEHIL | D79: MT | E79: 6 | F79: 138.86746 | G79: 97.207221 | H79: =F79*E79 -> 833.20475 | I79: =(E79*F79)*0.65 -> 541.58309 | J79: =(E79*(F79+G79)*(1+(SUM('Cadastro Institucional'!D$3:D$4)))) -> 1416.4481
A80: Instalações Elétricas - Eletrocalhas e Acessórios | B80: 1.6.2 | C80: TAMPA DE PRESSÃO C/REFORÇO EM CHAPA DE AÇO LISA, CH#20 MSG, Ref.: MAX.ET.PP-GE, NBR-10476, P/ELETROCALHA 300mm, FAB. MAXTIL,CARMEHIL | D80: MT | E80: 6 | F80: 71.488468 | G80: 50.041928 | H80: =F80*E80 -> 428.93081 | I80: =(E80*F80)*0.65 -> 278.80502 | J80: =(E80*(F80+G80)*(1+(SUM('Cadastro Institucional'!D$3:D$4)))) -> 729.18237
A81: Instalações Elétricas - Eletrocalhas e Acessórios | B81: 1.6.3 | C81: CURVA HORIZONTAL 90o EM CHAPA DE AÇO LISA, CH#18 MSG, Ref.: MAX.EL.CH9JI-GE, NBR-10476, P/ELETROCALHA 300x100mm, FAB. MAXTIL,CARMEHIL | D81: UN | E81: 2 | F81: 193.04681 | G81: 135.13277 | H81: =F81*E81 -> 386.09362 | I81: =(E81*F81)*0.65 -> 250.96085 | J81: =(E81*(F81+G81)*(1+(SUM('Cadastro Institucional'!D$3:D$4)))) -> 656.35915
A82: Instalações Elétricas - Eletrocalhas e Acessórios | B82: 1.6.4 | C82: CURVA DE INVERSÃO EM CHAPA DE AÇO LISA, CH#18 MSG, Ref.: MAX.EL.CE9JI-GF, NBR-6323, P/ELETROCALHA 300x100mm, FAB. MAXTIL,CARMEHIL | D82: UN | E82: 1 | F82: 128.69239 | G82: 90.084675 | H82: =F82*E82 -> 128.69239 | I82: =(E82*F82)*0.65 -> 83.650055 | J82: =(E82*(F82+G82)*(1+(SUM('Cadastro Institucional'!D$3:D$4)))) -> 218.77707
A83: Instalações Elétricas - Eletrocalhas e Acessórios | B83: 1.6.5 | C83: TE HORIZONTAL 90o EM CHAPA DE AÇO LISA, CH#18 MSG, Ref.: MAX.EL.TRJI-GE, NBR-10476, P/ELETROCALHA 300x100mm, FAB. MAXTIL, CARMEHIL | D83: UN | E83: 1 | F83: 128.69239 | G83: 90.084675 | H83: =F83*E83 -> 128.69239 | I83: =(E83*F83)*0.65 -> 83.650055 | J83: =(E83*(F83+G83)*(1+(SUM('Cadastro Institucional'!D$3:D$4)))) -> 218.77707
A84: Instalações Elétricas - Eletrocalhas e Acessórios | B84: 1.6.6 | C84: FLANGE P/PAINEL EM CHAPA DE AÇO LISA, CH#18 MSG, Ref.: MAX.E.ACO-GE, NBR-10476, P/ELETROCALHA 300x100mm, FAB. MAXTIL,CARMEHIL | D84: UN | E84: 1 | F84: 19.035099 | G84: 13.324569 | H84: =F84*E84 -> 19.035099 | I84: =(E84*F84)*0.65 -> 12.372814 | J84: =(E84*(F84+G84)*(1+(SUM('Cadastro Institucional'!D$3:D$4)))) -> 32.359668
A85: Instalações Elétricas - Eletrocalhas e Acessórios | B85: 1.6.7 | C85: TALA DE JUNÇÃO SIMPLES P/ELETROCALHA, CURTA A=100mm, 08 FUROS, B=95mm, Ref.: MAX.E.JSC.100, NBR-10476, FAB. MAXTIL, CARMEHIL | D85: UN | E85: 22 | F85: 5.2272552 | G85: 3.6590786 | H85: =F85*E85 -> 114.99961 | I85: =(E85*F85)*0.65 -> 74.749749 | J85: =(E85*(F85+G85)*(1+(SUM('Cadastro Institucional'!D$3:D$4)))) -> 195.49934
A86: Instalações Elétricas - Eletrocalhas e Acessórios | B86: 1.6.8 | C86: CHUMBADOR ROSCA INTERNA Ф1/4" x 31mm, Ref. MAX.ARS14, FAB. MAXTIL,CARMEHIL | D86: UN | E86: 66 | F86: 4.1916669 | G86: 2.9341668 | H86: =F86*E86 -> 276.65001 | I86: =(E86*F86)*0.65 -> 179.82251 | J86: =(E86*(F86+G86)*(1+(SUM('Cadastro Institucional'!D$3:D$4)))) -> 470.30503
A87: Instalações Elétricas - Eletrocalhas e Acessórios | B87: 1.6.9 | C87: VERGALHÃO (TIRANTE) AÇO GALVANIZADO, ROSCA TOTAL Ф 1/4", Ref. MAX.AF.BR.1/4, FAB. MAXTIL,CARMEHIL | D87: MT | E87: 36 | F87: 5.6020395 | G87: 3.9214277 | H87: =F87*E87 -> 201.67342 | I87: =(E87*F87)*0.65 -> 131.08772 | J87: =(E87*(F87+G87)*(1+(SUM('Cadastro Institucional'!D$3:D$4)))) -> 342.84482
...

Sheet Medição Consolidada (Itens de C
E1: OBRA | F1: ='Cadastro Institucional'!D$6 -> Condominio Palatium | G1: ='Cadastro Institucional'!D$7 -> 0
A2: CNPJ | B2: Razão Social | C2: Inscrição Estadual | D2: Responsável | E2: Cargo | F2: Telefone | G2: E-mail
A3: ='Cadastro Institucional'!D$10 -> 23.471.824/0001-45 | B3: ='Cadastro Institucional'!D$9 -> F A Alves Vasoncelos Ltda. | C3: ='Cadastro Institucional'!D$11 -> 0 | D3: ='Cadastro Institucional'!D$12 -> Francisco de Assis Alves Vasocnelos | E3: ='Cadastro Institucional'!D$13 -> Enegenheiro Responsável | F3: ='Cadastro Institucional'!D$14 -> (88) 9 8802-1038 | G3: ='Cadastro Institucional'!D$15 -> spateeng@gmail.com
A5: Etapa | B5: Item | C5: Descrição | D5: Quantidade Contratada | E5: Valor Contratado | F5: Saldo Total à Medir | G5: Quantidade Executada | H5: % Executado | I5: Valor Executado
A6: ='Itens de Contrato'!A6 -> Instalações Elétricas - Tubulações Laje aparente | B6: ='Itens de Contrato'!B6 -> 1.1.1 | C6: =VLOOKUP(B6,'Itens de Contrato'!B$5:J$873,2,0) -> ELETRODUTO PVC RÍGIDO ROSCÁVEL, CLASSE B, NBR-15465, Ф 3/4" x 3,0m, FAB.TIGRE, AMANCO | D6: 1907 | E6: =D6*('Itens de Contrato'!F6+'Itens de Contrato'!G6) -> 71248.808 | F6: =D6-G6 -> 1907 | G6: =SUM('Medição 01'!G6,'Medição 02'!G6,'Medição 03'!G6,'Medição 04'!G6,'Medição 05'!G6,'Medição 06'!G6,'Medição 07'!G6,'Medição 08'!G6,'Medição 09'!G6,'Medição 10'!G6,'Medição 11'!G6,'Medição 12'!G6) -> 0 | H6: =G6/D6 -> 0 | I6: =G6*('Itens de Contrato'!F6+'Itens de Contrato'!G6) -> 0
A7: ='Itens de Contrato'!A7 -> Instalações Elétricas - Tubulações Laje aparente | B7: ='Itens de Contrato'!B7 -> 1.1.2 | C7: =VLOOKUP(B7,'Itens de Contrato'!B$5:J$873,2,0) -> ELETRODUTO PVC RÍGIDO ROSCÁVEL, CLASSE B, NBR-15465, Ф 1" x 3,0m, FAB.TIGRE, AMANCO | D7: 31 | E7: =D7*('Itens de Contrato'!F7+'Itens de Contrato'!G7) -> 1846.038 | F7: =D7-G7 -> 31 | G7: =SUM('Medição 01'!G7,'Medição 02'!G7,'Medição 03'!G7,'Medição 04'!G7,'Medição 05'!G7,'Medição 06'!G7,'Medição 07'!G7,'Medição 08'!G7,'Medição 09'!G7,'Medição 10'!G7,'Medição 11'!G7,'Medição 12'!G7) -> 0 | H7: =G7/D7 -> 0 | I7: =G7*('Itens de Contrato'!F7+'Itens de Contrato'!G7) -> 0
A8: ='Itens de Contrato'!A8 -> Instalações Elétricas - Tubulações Laje aparente | B8: ='Itens de Contrato'!B8 -> 1.1.3 | C8: =VLOOKUP(B8,'Itens de Contrato'!B$5:J$873,2,0) -> CURVA 90o P/ELETRODUTO PVC RÍGIDO, ROSCA Ф 3/4", FAB.TIGRE, AMANCO | D8: 1653 | E8: =D8*('Itens de Contrato'!F8+'Itens de Contrato'!G8) -> 13996.227 | F8: =D8-G8 -> 1653 | G8: =SUM('Medição 01'!G8,'Medição 02'!G8,'Medição 03'!G8,'Medição 04'!G8,'Medição 05'!G8,'Medição 06'!G8,'Medição 07'!G8,'Medição 08'!G8,'Medição 09'!G8,'Medição 10'!G8,'Medição 11'!G8,'Medição 12'!G8) -> 0 | H8: =G8/D8 -> 0 | I8: =G8*('Itens de Contrato'!F8+'Itens de Contrato'!G8) -> 0
A9: ='Itens de Contrato'!A9 -> Instalações Elétricas - Tubulações Laje aparente | B9: ='Itens de Contrato'!B9 -> 1.1.4 | C9: =VLOOKUP(B9,'Itens de Contrato'!B$5:J$873,2,0) -> CURVA 90o P/ELETRODUTO PVC RÍGIDO, ROSCA Ф 1", FAB.TIGRE, AMANCO | D9: 3 | E9: =D9*('Itens de Contrato'!F9+'Itens de Contrato'!G9) -> 36.216002 | F9: =D9-G9 -> 3 | G9: =SUM('Medição 01'!G9,'Medição 02'!G9,'Medição 03'!G9,'Medição 04'!G9,'Medição 05'!G9,'Medição 06'!G9,'Medição 07'!G9,'Medição 08'!G9,'Medição 09'!G9,'Medição 10'!G9,'Medição 11'!G9,'Medição 12'!G9) -> 0 | H9: =G9/D9 -> 0 | I9: =G9*('Itens de Contrato'!F9+'Itens de Contrato'!G9) -> 0
A10: ='Itens de Contrato'!A10 -> Instalações Elétricas - Tubulações Laje aparente | B10: ='Itens de Contrato'!B10 -> 1.1.5 | C10: =VLOOKUP(B10,'Itens de Contrato'!B$5:J$873,2,0) -> LUVA P/ELETRODUTO PVC RÍGIDO, ROSCA Ф 3/4", FAB.TIGRE, AMANCO | D10: 3560 | E10: =D10*('Itens de Contrato'!F10+'Itens de Contrato'!G10) -> 16016.639 | F10: =D10-G10 -> 3560 | G10: =SUM('Medição 01'!G10,'Medição 02'!G10,'Medição 03'!G10,'Medição 04'!G10,'Medição 05'!G10,'Medição 06'!G10,'Medição 07'!G10,'Medição 08'!G10,'Medição 09'!G10,'Medição 10'!G10,'Medição 11'!G10,'Medição 12'!G10) -> 0 | H10: =G10/D10 -> 0 | I10: =G10*('Itens de Contrato'!F10+'Itens de Contrato'!G10) -> 0
A11: ='Itens de Contrato'!A11 -> Instalações Elétricas - Tubulações Laje aparente | B11: ='Itens de Contrato'!B11 -> 1.1.6 | C11: =VLOOKUP(B11,'Itens de Contrato'!B$5:J$873,2,0) -> LUVA P/ELETRODUTO PVC RÍGIDO, ROSCA Ф 1", FAB.TIGRE, AMANCO | D11: 34 | E11: =D11*('Itens de Contrato'!F11+'Itens de Contrato'!G11) -> 246.07879 | F11: =D11-G11 -> 34 | G11: =SUM('Medição 01'!G11,'Medição 02'!G11,'Medição 03'!G11,'Medição 04'!G11,'Medição 05'!G11,'Medição 06'!G11,'Medição 07'!G11,'Medição 08'!G11,'Medição 09'!G11,'Medição 10'!G11,'Medição 11'!G11,'Medição 12'!G11) -> 0 | H11: =G11/D11 -> 0 | I11: =G11*('Itens de Contrato'!F11+'Itens de Contrato'!G11) -> 0
A12: ='Itens de Contrato'!A12 -> Instalações Elétricas - Tubulações Laje aparente | B12: ='Itens de Contrato'!B12 -> 1.1.7 | C12: =VLOOKUP(B12,'Itens de Contrato'!B$5:J$873,2,0) -> BUCHA E ARRUELA EM LIGA DE ALUMINIO SILÍCIO Ф 3/4", FAB. WETZEL, TRAMONTINA | D12: 2914 | E12: =D12*('Itens de Contrato'!F12+'Itens de Contrato'!G12) -> 17751.765 | F12: =D12-G12 -> 2914 | G12: =SUM('Medição 01'!G12,'Medição 02'!G12,'Medição 03'!G12,'Medição 04'!G12,'Medição 05'!G12,'Medição 06'!G12,'Medição 07'!G12,'Medição 08'!G12,'Medição 09'!G12,'Medição 10'!G12,'Medição 11'!G12,'Medição 12'!G12) -> 0 | H12: =G12/D12 -> 0 | I12: =G12*('Itens de Contrato'!F12+'Itens de Contrato'!G12) -> 0
A13: ='Itens de Contrato'!A13 -> Instalações Elétricas - Tubulações Laje aparente | B13: ='Itens de Contrato'!B13 -> 1.1.8 | C13: =VLOOKUP(B13,'Itens de Contrato'!B$5:J$873,2,0) -> ARAME GALVANIZADO BITOLA 16BWG - GERDAU | D13: 55 | E13: =D13*('Itens de Contrato'!F13+'Itens de Contrato'!G13) -> 3980.6863 | F13: =D13-G13 -> 55 | G13: =SUM('Medição 01'!G13,'Medição 02'!G13,'Medição 03'!G13,'Medição 04'!G13,'Medição 05'!G13,'Medição 06'!G13,'Medição 07'!G13,'Medição 08'!G13,'Medição 09'!G13,'Medição 10'!G13,'Medição 11'!G13,'Medição 12'!G13) -> 0 | H13: =G13/D13 -> 0 | I13: =G13*('Itens de Contrato'!F13+'Itens de Contrato'!G13) -> 0
A14: ='Itens de Contrato'!A14 -> Instalações Elétricas - Tubulações Laje aparente | B14: ='Itens de Contrato'!B14 -> 1.1.9 | C14: =VLOOKUP(B14,'Itens de Contrato'!B$5:J$873,2,0) -> PARAFUSO FENDA, ROSCA SOBERBA C/BUCHA DE NYLON Ref. S8 x 40mm, FAB. MAXTIL,CARMEHIL | D14: 3829 | E14: =D14*('Itens de Contrato'!F14+'Itens de Contrato'!G14) -> 9308.9377 | F14: =D14-G14 -> 3829 | G14: =SUM('Medição 01'!G14,'Medição 02'!G14,'Medição 03'!G14,'Medição 04'!G14,'Medição 05'!G14,'Medição 06'!G14,'Medição 07'!G14,'Medição 08'!G14,'Medição 09'!G14,'Medição 10'!G14,'Medição 11'!G14,'Medição 12'!G14) -> 0 | H14: =G14/D14 -> 0 | I14: =G14*('Itens de Contrato'!F14+'Itens de Contrato'!G14) -> 0
A15: ='Itens de Contrato'!A15 -> Instalações Elétricas - Tubulações Laje aparente | B15: ='Itens de Contrato'!B15 -> 1.1.10 | C15: =VLOOKUP(B15,'Itens de Contrato'!B$5:J$873,2,0) -> ABRAÇADEIRA AÇO GALVANIZADO, TIPO "D" C/CUNHA Ф 3/4", Ref. MAX.AA.TDC, FAB. MAXTIL,CARMEHIL | D15: 2922 | E15: =D15*('Itens de Contrato'!F15+'Itens de Contrato'!G15) -> 6777.2547 | F15: =D15-G15 -> 2922 | G15: =SUM('Medição 01'!G15,'Medição 02'!G15,'Medição 03'!G15,'Medição 04'!G15,'Medição 05'!G15,'Medição 06'!G15,'Medição 07'!G15,'Medição 08'!G15,'Medição 09'!G15,'Medição 10'!G15,'Medição 11'!G15,'Medição 12'!G15) -> 0 | H15: =G15/D15 -> 0 | I15: =G15*('Itens de Contrato'!F15+'Itens de Contrato'!G15) -> 0
A16: ='Itens de Contrato'!A16 -> Instalações Elétricas - Tubulações Laje aparente | B16: ='Itens de Contrato'!B16 -> 1.1.11 | C16: =VLOOKUP(B16,'Itens de Contrato'!B$5:J$873,2,0) -> CONDULETE MÚLTIPLO EM LIGA DE ALUMÍNIO, PARAF. AÇO ZINCADO, TAMPA E JUNTA DE VEDAÇÃO, ROSCA Ф 3/4", FAB. WETZEL | D16: 68 | E16: =D16*('Itens de Contrato'!F16+'Itens de Contrato'!G16) -> 2650.8101 | F16: =D16-G16 -> 68 | G16: =SUM('Medição 01'!G16,'Medição 02'!G16,'Medição 03'!G16,'Medição 04'!G16,'Medição 05'!G16,'Medição 06'!G16,'Medição 07'!G16,'Medição 08'!G16,'Medição 09'!G16,'Medição 10'!G16,'Medição 11'!G16,'Medição 12'!G16) -> 0 | H16: =G16/D16 -> 0 | I16: =G16*('Itens de Contrato'!F16+'Itens de Contrato'!G16) -> 0
A17: ='Itens de Contrato'!A17 -> Instalações Elétricas - Tubulações Laje aparente | B17: ='Itens de Contrato'!B17 -> 1.1.12 | C17: =VLOOKUP(B17,'Itens de Contrato'!B$5:J$873,2,0) -> CONECTOR EM ALUM.SILICIO P/CONDULETE MÚLTIPLO, PARAF. AÇO ZINCADO, ROSCA EXTERNA Ф 3/4", FAB. WETZEL | D17: 204 | E17: =D17*('Itens de Contrato'!F17+'Itens de Contrato'!G17) -> 666.97804 | F17: =D17-G17 -> 204 | G17: =SUM('Medição 01'!G17,'Medição 02'!G17,'Medição 03'!G17,'Medição 04'!G17,'Medição 05'!G17,'Medição 06'!G17,'Medição 07'!G17,'Medição 08'!G17,'Medição 09'!G17,'Medição 10'!G17,'Medição 11'!G17,'Medição 12'!G17) -> 0 | H17: =G17/D17 -> 0 | I17: =G17*('Itens de Contrato'!F17+'Itens de Contrato'!G17) -> 0
... A873: ='Itens de Contrato'!A873 -> Sistema de Climatização - Lazer - 01 AC 60000 BTU/h | B873: ='Itens de Contrato'!B873 -> 7.7.5 | C873: =VLOOKUP(B873,'Itens de Contrato'!B$5:J$873,2,0) -> CABO PP FLEX ISOL. 450/750V / PVC 70oC, CL.5, NBR-Nm247-5, 4x2,5mm2 FAB. COBRECOM | D873: 30 | E873: =D873*('Itens de Contrato'!F873+'Itens de Contrato'!G873) -> 708.3917 | F873: =D873-G873 -> 30 | G873: =SUM('Medição 01'!G873,'Medição 02'!G873,'Medição 03'!G873,'Medição 04'!G873,'Medição 05'!G873,'Medição 06'!G873,'Medição 07'!G873,'Medição 08'!G873,'Medição 09'!G873,'Medição 10'!G873,'Medição 11'!G873,'Medição 12'!G873) -> 0 | H873: =G873/D873 -> 0 | I873: =G873*('Itens de Contrato'!F873+'Itens de Contrato'!G873) -> 0
E874: =SUM(E6:E873) -> 4982448.6

Sheet Medição Consolidada (Etapas)
E1: OBRA | F1: ='Cadastro Institucional'!D$6 -> Condominio Palatium | G1: ='Cadastro Institucional'!D$7 -> 0
A2: CNPJ | B2: Razão Social | C2: Inscrição Estadual | D2: Responsável | E2: Cargo | F2: Telefone | G2: E-mail
A3: ='Cadastro Institucional'!D$10 -> 23.471.824/0001-45 | B3: ='Cadastro Institucional'!D$9 -> F A Alves Vasoncelos Ltda. | C3: ='Cadastro Institucional'!D$11 -> 0 | D3: ='Cadastro Institucional'!D$12 -> Francisco de Assis Alves Vasocnelos | E3: ='Cadastro Institucional'!D$13 -> Enegenheiro Responsável | F3: ='Cadastro Institucional'!D$14 -> (88) 9 8802-1038 | G3: ='Cadastro Institucional'!D$15 -> spateeng@gmail.com
A5: Nº | B5: Etapa | C5: Quantidade Contratada | D5: Valor Contratado | E5: Saldo Total à Medir | F5: Quantidade Executada | G5: % Executado | H5: Valor Executado
A6: =Etapas!A6 -> 1.1 | B6: =Etapas!B6 -> Instalações Elétricas - Tubulações Laje aparente | C6: =SUMIF('Medição 01'!$A:$A,$B6,'Medição 01'!D:D) -> 18093 | D6: =SUMIF('Medição 01'!$A:$A,$B6,'Medição 01'!E:E) -> 155657.8 | E6: =SUMIF('Medição 01'!$A:$A,$B6,'Medição 01'!F:F) -> 18093 | F6: =SUMIF('Medição 01'!$A:$A,$B6,'Medição 01'!G:G) -> 0 | G6: =F6/C6 -> 0 | H6: =F6*('Itens de Contrato'!F6+'Itens de Contrato'!G6) -> 0
A7: =Etapas!A7 -> 1.2 | B7: =Etapas!B7 -> Instalações Elétricas - Tubulações Piso e paredes | C7: =SUMIF('Medição 01'!$A:$A,$B7,'Medição 01'!D:D) -> 6268 | D7: =SUMIF('Medição 01'!$A:$A,$B7,'Medição 01'!E:E) -> 41618.334 | E7: =SUMIF('Medição 01'!$A:$A,$B7,'Medição 01'!F:F) -> 6268 | F7: =SUMIF('Medição 01'!$A:$A,$B7,'Medição 01'!G:G) -> 0 | G7: =F7/C7 -> 0 | H7: =F7*('Itens de Contrato'!F7+'Itens de Contrato'!G7) -> 0
A8: =Etapas!A8 -> 1.3 | B8: =Etapas!B8 -> Instalações Elétricas - Fiação de Distribuição | C8: =SUMIF('Medição 01'!$A:$A,$B8,'Medição 01'!D:D) -> 47739 | D8: =SUMIF('Medição 01'!$A:$A,$B8,'Medição 01'!E:E) -> 303963 | E8: =SUMIF('Medição 01'!$A:$A,$B8,'Medição 01'!F:F) -> 47739 | F8: =SUMIF('Medição 01'!$A:$A,$B8,'Medição 01'!G:G) -> 0 | G8: =F8/C8 -> 0 | H8: =F8*('Itens de Contrato'!F8+'Itens de Contrato'!G8) -> 0
A9: =Etapas!A9 -> 1.4 | B9: =Etapas!B9 -> Instalações Elétricas - Tomadas e Interruptores | C9: =SUMIF('Medição 01'!$A:$A,$B9,'Medição 01'!D:D) -> 1787 | D9: =SUMIF('Medição 01'!$A:$A,$B9,'Medição 01'!E:E) -> 131104.33 | E9: =SUMIF('Medição 01'!$A:$A,$B9,'Medição 01'!F:F) -> 1787 | F9: =SUMIF('Medição 01'!$A:$A,$B9,'Medição 01'!G:G) -> 0 | G9: =F9/C9 -> 0 | H9: =F9*('Itens de Contrato'!F9+'Itens de Contrato'!G9) -> 0
A10: =Etapas!A10 -> 1.5 | B10: =Etapas!B10 -> Instalações Elétricas - Luminárias e Acessórios (Somente Mão de Obra) | C10: =SUMIF('Medição 01'!$A:$A,$B10,'Medição 01'!D:D) -> 533 | D10: =SUMIF('Medição 01'!$A:$A,$B10,'Medição 01'!E:E) -> 12127.83 | E10: =SUMIF('Medição 01'!$A:$A,$B10,'Medição 01'!F:F) -> 533 | F10: =SUMIF('Medição 01'!$A:$A,$B10,'Medição 01'!G:G) -> 0 | G10: =F10/C10 -> 0 | H10: =F10*('Itens de Contrato'!F10+'Itens de Contrato'!G10) -> 0
A11: =Etapas!A11 -> 1.6 | B11: =Etapas!B11 -> Instalações Elétricas - Eletrocalhas e Acessórios | C11: =SUMIF('Medição 01'!$A:$A,$B11,'Medição 01'!D:D) -> 510 | D11: =SUMIF('Medição 01'!$A:$A,$B11,'Medição 01'!E:E) -> 8071.5632 | E11: =SUMIF('Medição 01'!$A:$A,$B11,'Medição 01'!F:F) -> 510 | F11: =SUMIF('Medição 01'!$A:$A,$B11,'Medição 01'!G:G) -> 0 | G11: =F11/C11 -> 0 | H11: =F11*('Itens de Contrato'!F11+'Itens de Contrato'!G11) -> 0
A12: =Etapas!A12 -> 1.7 | B12: =Etapas!B12 -> Instalações Elétricas - Quadros - Infraestrutura | C12: =SUMIF('Medição 01'!$A:$A,$B12,'Medição 01'!D:D) -> 3404 | D12: =SUMIF('Medição 01'!$A:$A,$B12,'Medição 01'!E:E) -> 60376.467 | E12: =SUMIF('Medição 01'!$A:$A,$B12,'Medição 01'!F:F) -> 3404 | F12: =SUMIF('Medição 01'!$A:$A,$B12,'Medição 01'!G:G) -> 0 | G12: =F12/C12 -> 0 | H12: =F12*('Itens de Contrato'!F12+'Itens de Contrato'!G12) -> 0
A13: =Etapas!A13 -> 1.8 | B13: =Etapas!B13 -> Instalações Elétricas - Quadros - Cabeamento | C13: =SUMIF('Medição 01'!$A:$A,$B13,'Medição 01'!D:D) -> 6689 | D13: =SUMIF('Medição 01'!$A:$A,$B13,'Medição 01'!E:E) -> 302424.81 | E13: =SUMIF('Medição 01'!$A:$A,$B13,'Medição 01'!F:F) -> 6689 | F13: =SUMIF('Medição 01'!$A:$A,$B13,'Medição 01'!G:G) -> 0 | G13: =F13/C13 -> 0 | H13: =F13*('Itens de Contrato'!F13+'Itens de Contrato'!G13) -> 0
A14: =Etapas!A14 -> 1.9 | B14: =Etapas!B14 -> Instalações Elétricas - Quadros | C14: =SUMIF('Medição 01'!$A:$A,$B14,'Medição 01'!D:D) -> 42 | D14: =SUMIF('Medição 01'!$A:$A,$B14,'Medição 01'!E:E) -> 352980.27 | E14: =SUMIF('Medição 01'!$A:$A,$B14,'Medição 01'!F:F) -> 42 | F14: =SUMIF('Medição 01'!$A:$A,$B14,'Medição 01'!G:G) -> 0 | G14: =F14/C14 -> 0 | H14: =F14*('Itens de Contrato'!F14+'Itens de Contrato'!G14) -> 0
A15: =Etapas!A15 -> 2.1 | B15: =Etapas!B15 -> Instalações de Telecom/Infra CFTV - Tubulações Laje aparente e paredes | C15: =SUMIF('Medição 01'!$A:$A,$B15,'Medição 01'!D:D) -> 6198 | D15: =SUMIF('Medição 01'!$A:$A,$B15,'Medição 01'!E:E) -> 83136.096 | E15: =SUMIF('Medição 01'!$A:$A,$B15,'Medição 01'!F:F) -> 6198 | F15: =SUMIF('Medição 01'!$A:$A,$B15,'Medição 01'!G:G) -> 0 | G15: =F15/C15 -> 0 | H15: =F15*('Itens de Contrato'!F15+'Itens de Contrato'!G15) -> 0
A16: =Etapas!A16 -> 2.2 | B16: =Etapas!B16 -> Instalações de Telecom/Infra CFTV - Tomadas e afins | C16: =SUMIF('Medição 01'!$A:$A,$B16,'Medição 01'!D:D) -> 200 | D16: =SUMIF('Medição 01'!$A:$A,$B16,'Medição 01'!E:E) -> 19745.965 | E16: =SUMIF('Medição 01'!$A:$A,$B16,'Medição 01'!F:F) -> 200 | F16: =SUMIF('Medição 01'!$A:$A,$B16,'Medição 01'!G:G) -> 0 | G16: =F16/C16 -> 0 | H16: =F16*('Itens de Contrato'!F16+'Itens de Contrato'!G16) -> 0
A17: =Etapas!A17 -> 2.3 | B17: =Etapas!B17 -> Instalações de Telecom/Infra CFTV - Fiação de distribuição | C17: =SUMIF('Medição 01'!$A:$A,$B17,'Medição 01'!D:D) -> 1905 | D17: =SUMIF('Medição 01'!$A:$A,$B17,'Medição 01'!E:E) -> 9560.4936 | E17: =SUMIF('Medição 01'!$A:$A,$B17,'Medição 01'!F:F) -> 1905 | F17: =SUMIF('Medição 01'!$A:$A,$B17,'Medição 01'!G:G) -> 0 | G17: =F17/C17 -> 0 | H17: =F17*('Itens de Contrato'!F17+'Itens de Contrato'!G17) -> 0
... A47: =Etapas!A47 -> 7.7 | B47: =Etapas!B47 -> Sistema de Climatização - Lazer - 01 AC 60000 BTU/h | C47: =SUMIF('Medição 01'!$A:$A,$B47,'Medição 01'!D:D) -> 112 | D47: =SUMIF('Medição 01'!$A:$A,$B47,'Medição 01'!E:E) -> 9647.4567 | E47: =SUMIF('Medição 01'!$A:$A,$B47,'Medição 01'!F:F) -> 112 | F47: =SUMIF('Medição 01'!$A:$A,$B47,'Medição 01'!G:G) -> 0 | G47: =F47/C47 -> 0 | H47: =F47*('Itens de Contrato'!F47+'Itens de Contrato'!G47) -> 0
D48: =SUM(D6:D47) -> 4747875.7

Sheet Medição 01
E1: OBRA | F1: ='Cadastro Institucional'!D$6 -> Condominio Palatium | G1: ='Cadastro Institucional'!D$7 -> 0
A2: CNPJ | B2: Razão Social | C2: Inscrição Estadual | D2: Responsável | E2: Cargo | F2: Telefone | G2: E-mail | H2: Medição Nº | I2: Período
A3: ='Cadastro Institucional'!D$10 -> 23.471.824/0001-45 | B3: ='Cadastro Institucional'!D$9 -> F A Alves Vasoncelos Ltda. | C3: ='Cadastro Institucional'!D$11 -> 0 | D3: ='Cadastro Institucional'!D$12 -> Francisco de Assis Alves Vasocnelos | E3: ='Cadastro Institucional'!D$13 -> Enegenheiro Responsável | F3: ='Cadastro Institucional'!D$14 -> (88) 9 8802-1038 | G3: ='Cadastro Institucional'!D$15 -> spateeng@gmail.com
A5: Etapa | B5: Item | C5: Descrição | D5: Quantidade Contratada | E5: Valor Contratado | F5: Saldo Total à Medir | G5: Quantidade Executada | H5: % Executado | I5: Valor Executado | K5: Preencha apenas as células com esse azul claro como cor de fundo!
A6: ='Itens de Contrato'!A6 -> Instalações Elétricas - Tubulações Laje aparente | B6: ='Itens de Contrato'!B6 -> 1.1.1 | C6: =VLOOKUP(B6,'Itens de Contrato'!B$6:J$873,2,0) -> ELETRODUTO PVC RÍGIDO ROSCÁVEL, CLASSE B, NBR-15465, Ф 3/4" x 3,0m, FAB.TIGRE, AMANCO | D6: ='Itens de Contrato'!E6 -> 1907 | E6: =D6*('Itens de Contrato'!F6 + 'Itens de Contrato'!G6) -> 71248.808 | F6: ='Itens de Contrato'!E6 -> 1907 | G6: 0 | H6: =G6/D6 -> 0 | I6: =G6*('Itens de Contrato'!F6+'Itens de Contrato'!G6) -> 0
A7: ='Itens de Contrato'!A7 -> Instalações Elétricas - Tubulações Laje aparente | B7: ='Itens de Contrato'!B7 -> 1.1.2 | C7: =VLOOKUP(B7,'Itens de Contrato'!B$6:J$873,2,0) -> ELETRODUTO PVC RÍGIDO ROSCÁVEL, CLASSE B, NBR-15465, Ф 1" x 3,0m, FAB.TIGRE, AMANCO | D7: ='Itens de Contrato'!E7 -> 31 | E7: =D7*('Itens de Contrato'!F7 + 'Itens de Contrato'!G7) -> 1846.038 | F7: ='Itens de Contrato'!E7 -> 31 | H7: =G7/D7 -> 0 | I7: =G7*('Itens de Contrato'!F7+'Itens de Contrato'!G7) -> 0
A8: ='Itens de Contrato'!A8 -> Instalações Elétricas - Tubulações Laje aparente | B8: ='Itens de Contrato'!B8 -> 1.1.3 | C8: =VLOOKUP(B8,'Itens de Contrato'!B$6:J$873,2,0) -> CURVA 90o P/ELETRODUTO PVC RÍGIDO, ROSCA Ф 3/4", FAB.TIGRE, AMANCO | D8: ='Itens de Contrato'!E8 -> 1653 | E8: =D8*('Itens de Contrato'!F8 + 'Itens de Contrato'!G8) -> 13996.227 | F8: ='Itens de Contrato'!E8 -> 1653 | H8: =G8/D8 -> 0 | I8: =G8*('Itens de Contrato'!F8+'Itens de Contrato'!G8) -> 0
A9: ='Itens de Contrato'!A9 -> Instalações Elétricas - Tubulações Laje aparente | B9: ='Itens de Contrato'!B9 -> 1.1.4 | C9: =VLOOKUP(B9,'Itens de Contrato'!B$6:J$873,2,0) -> CURVA 90o P/ELETRODUTO PVC RÍGIDO, ROSCA Ф 1", FAB.TIGRE, AMANCO | D9: ='Itens de Contrato'!E9 -> 3 | E9: =D9*('Itens de Contrato'!F9 + 'Itens de Contrato'!G9) -> 36.216002 | F9: ='Itens de Contrato'!E9 -> 3 | H9: =G9/D9 -> 0 | I9: =G9*('Itens de Contrato'!F9+'Itens de Contrato'!G9) -> 0
A10: ='Itens de Contrato'!A10 -> Instalações Elétricas - Tubulações Laje aparente | B10: ='Itens de Contrato'!B10 -> 1.1.5 | C10: =VLOOKUP(B10,'Itens de Contrato'!B$6:J$873,2,0) -> LUVA P/ELETRODUTO PVC RÍGIDO, ROSCA Ф 3/4", FAB.TIGRE, AMANCO | D10: ='Itens de Contrato'!E10 -> 3560 | E10: =D10*('Itens de Contrato'!F10 + 'Itens de Contrato'!G10) -> 16016.639 | F10: ='Itens de Contrato'!E10 -> 3560 | H10: =G10/D10 -> 0 | I10: =G10*('Itens de Contrato'!F10+'Itens de Contrato'!G10) -> 0
A11: ='Itens de Contrato'!A11 -> Instalações Elétricas - Tubulações Laje aparente | B11: ='Itens de Contrato'!B11 -> 1.1.6 | C11: =VLOOKUP(B11,'Itens de Contrato'!B$6:J$873,2,0) -> LUVA P/ELETRODUTO PVC RÍGIDO, ROSCA Ф 1", FAB.TIGRE, AMANCO | D11: ='Itens de Contrato'!E11 -> 34 | E11: =D11*('Itens de Contrato'!F11 + 'Itens de Contrato'!G11) -> 246.07879 | F11: ='Itens de Contrato'!E11 -> 34 | H11: =G11/D11 -> 0 | I11: =G11*('Itens de Contrato'!F11+'Itens de Contrato'!G11) -> 0
A12: ='Itens de Contrato'!A12 -> Instalações Elétricas - Tubulações Laje aparente | B12: ='Itens de Contrato'!B12 -> 1.1.7 | C12: =VLOOKUP(B12,'Itens de Contrato'!B$6:J$873,2,0) -> BUCHA E ARRUELA EM LIGA DE ALUMINIO SILÍCIO Ф 3/4", FAB. WETZEL, TRAMONTINA | D12: ='Itens de Contrato'!E12 -> 2914 | E12: =D12*('Itens de Contrato'!F12 + 'Itens de Contrato'!G12) -> 17751.765 | F12: ='Itens de Contrato'!E12 -> 2914 | H12: =G12/D12 -> 0 | I12: =G12*('Itens de Contrato'!F12+'Itens de Contrato'!G12) -> 0
A13: ='Itens de Contrato'!A13 -> Instalações Elétricas - Tubulações Laje aparente | B13: ='Itens de Contrato'!B13 -> 1.1.8 | C13: =VLOOKUP(B13,'Itens de Contrato'!B$6:J$873,2,0) -> ARAME GALVANIZADO BITOLA 16BWG - GERDAU | D13: ='Itens de Contrato'!E13 -> 55 | E13: =D13*('Itens de Contrato'!F13 + 'Itens de Contrato'!G13) -> 3980.6863 | F13: ='Itens de Contrato'!E13 -> 55 | H13: =G13/D13 -> 0 | I13: =G13*('Itens de Contrato'!F13+'Itens de Contrato'!G13) -> 0
A14: ='Itens de Contrato'!A14 -> Instalações Elétricas - Tubulações Laje aparente | B14: ='Itens de Contrato'!B14 -> 1.1.9 | C14: =VLOOKUP(B14,'Itens de Contrato'!B$6:J$873,2,0) -> PARAFUSO FENDA, ROSCA SOBERBA C/BUCHA DE NYLON Ref. S8 x 40mm, FAB. MAXTIL,CARMEHIL | D14: ='Itens de Contrato'!E14 -> 3829 | E14: =D14*('Itens de Contrato'!F14 + 'Itens de Contrato'!G14) -> 9308.9377 | F14: ='Itens de Contrato'!E14 -> 3829 | H14: =G14/D14 -> 0 | I14: =G14*('Itens de Contrato'!F14+'Itens de Contrato'!G14) -> 0
A15: ='Itens de Contrato'!A15 -> Instalações Elétricas - Tubulações Laje aparente | B15: ='Itens de Contrato'!B15 -> 1.1.10 | C15: =VLOOKUP(B15,'Itens de Contrato'!B$6:J$873,2,0) -> ABRAÇADEIRA AÇO GALVANIZADO, TIPO "D" C/CUNHA Ф 3/4", Ref. MAX.AA.TDC, FAB. MAXTIL,CARMEHIL | D15: ='Itens de Contrato'!E15 -> 2922 | E15: =D15*('Itens de Contrato'!F15 + 'Itens de Contrato'!G15) -> 6777.2547 | F15: ='Itens de Contrato'!E15 -> 2922 | H15: =G15/D15 -> 0 | I15: =G15*('Itens de Contrato'!F15+'Itens de Contrato'!G15) -> 0
A16: ='Itens de Contrato'!A16 -> Instalações Elétricas - Tubulações Laje aparente | B16: ='Itens de Contrato'!B16 -> 1.1.11 | C16: =VLOOKUP(B16,'Itens de Contrato'!B$6:J$873,2,0) -> CONDULETE MÚLTIPLO EM LIGA DE ALUMÍNIO, PARAF. AÇO ZINCADO, TAMPA E JUNTA DE VEDAÇÃO, ROSCA Ф 3/4", FAB. WETZEL | D16: ='Itens de Contrato'!E16 -> 68 | E16: =D16*('Itens de Contrato'!F16 + 'Itens de Contrato'!G16) -> 2650.8101 | F16: ='Itens de Contrato'!E16 -> 68 | H16: =G16/D16 -> 0 | I16: =G16*('Itens de Contrato'!F16+'Itens de Contrato'!G16) -> 0
A17: ='Itens de Contrato'!A17 -> Instalações Elétricas - Tubulações Laje aparente | B17: ='Itens de Contrato'!B17 -> 1.1.12 | C17: =VLOOKUP(B17,'Itens de Contrato'!B$6:J$873,2,0) -> CONECTOR EM ALUM.SILICIO P/CONDULETE MÚLTIPLO, PARAF. AÇO ZINCADO, ROSCA EXTERNA Ф 3/4", FAB. WETZEL | D17: ='Itens de Contrato'!E17 -> 204 | E17: =D17*('Itens de Contrato'!F17 + 'Itens de Contrato'!G17) -> 666.97804 | F17: ='Itens de Contrato'!E17 -> 204 | H17: =G17/D17 -> 0 | I17: =G17*('Itens de Contrato'!F17+'Itens de Contrato'!G17) -> 0
A18: ='Itens de Contrato'!A18 -> Instalações Elétricas - Tubulações Laje aparente | B18: ='Itens de Contrato'!B18 -> 1.1.13 | C18: =VLOOKUP(B18,'Itens de Contrato'!B$6:J$873,2,0) -> CAIXA DE PVC QUADRADA 4"x4" (AMARELA), FAB.TIGRE, AMANCO | D18: ='Itens de Contrato'!E18 -> 6 | E18: =D18*('Itens de Contrato'!F18 + 'Itens de Contrato'!G18) -> 55.330003 | F18: ='Itens de Contrato'!E18 -> 6 | H18: =G18/D18 -> 0 | I18: =G18*('Itens de Contrato'!F18+'Itens de Contrato'!G18) -> 0
... A229: ='Itens de Contrato'!A229 -> Instalações de Telecom/Infra CFTV - Alimentadores dos Quadros | B229: ='Itens de Contrato'!B229 -> 2.4.31 | C229: =VLOOKUP(B229,'Itens de Contrato'!B$6:J$873,2,0) -> ABRAÇADEIRA DE NYLON INCOLOR 180x3,4mm, FAB. HELLERMANN, PIAL | D229: ='Itens de Contrato'!E229 -> 180 | E229: =D229*('Itens de Contrato'!F229 + 'Itens de Contrato'!G229) -> 125.75001 | F229: ='Itens de Contrato'!E229 -> 180 | H229: =G229/D229 -> 0 | I229: =G229*('Itens de Contrato'!F229+'Itens de Contrato'!G229) -> 0
A230: ='Itens de Contrato'!A230 -> Instalações Hidráulicas - AF Isométricos | B230: ='Itens de Contrato'!B230 -> 3.1.1 | C230: =VLOOKUP(B230,'Itens de Contrato'!B$6:J$873,2,0) -> TUBO PVC SOLDÁVEL, LINHA PREDIAL, NBR-5648, Ф 25mm x 6,0m, FAB. TIGRE, AMANCO | D230: 29 | E230: =D230*('Itens de Contrato'!F230 + 'Itens de Contrato'!G230) -> 1644.6843 | F230: ='Itens de Contrato'!E230 -> 201 | G230: 0 | H230: =G230/D230 -> 0 | I230: =G230*('Itens de Contrato'!F230+'Itens de Contrato'!G230) -> 0
A231: ='Itens de Contrato'!A231 -> Instalações Hidráulicas - AF Isométricos | B231: ='Itens de Contrato'!B231 -> 3.1.2 | C231: =VLOOKUP(B231,'Itens de Contrato'!B$6:J$873,2,0) -> TUBO PVC SOLDÁVEL, LINHA PREDIAL, NBR-5648, Ф 32mm x 6,0m, FAB. TIGRE, AMANCO | D231: 1.3076923 | E231: =D231*('Itens de Contrato'!F231 + 'Itens de Contrato'!G231) -> 213.59084 | F231: ='Itens de Contrato'!E231 -> 8.5 | H231: =G231/D231 -> 0 | I231: =G231*('Itens de Contrato'!F231+'Itens de Contrato'!G231) -> 0
A232: ='Itens de Contrato'!A232 -> Instalações Hidráulicas - AF Isométricos | B232: ='Itens de Contrato'!B232 -> 3.1.3 | C232: =VLOOKUP(B232,'Itens de Contrato'!B$6:J$873,2,0) -> LUVA SIMPLES PVC SOLDÁVEL, P/TUBO Ф 25mm, FAB.TIGRE, AMANCO | D232: 14 | E232: =D232*('Itens de Contrato'!F232 + 'Itens de Contrato'!G232) -> 27.776779 | F232: ='Itens de Contrato'!E232 -> 96.5 | H232: =G232/D232 -> 0 | I232: =G232*('Itens de Contrato'!F232+'Itens de Contrato'!G232) -> 0
A233: ='Itens de Contrato'!A233 -> Instalações Hidráulicas - AF Isométricos | B233: ='Itens de Contrato'!B233 -> 3.1.4 | C233: =VLOOKUP(B233,'Itens de Contrato'!B$6:J$873,2,0) -> JOELHO 90o PVC SOLDÁVEL, P/TUBO Ф 25mm, FAB.TIGRE, AMANCO | D233: 52 | E233: =D233*('Itens de Contrato'!F233 + 'Itens de Contrato'!G233) -> 69.109968 | F233: ='Itens de Contrato'!E233 -> 716 | H233: =G233/D233 -> 0 | I233: =G233*('Itens de Contrato'!F233+'Itens de Contrato'!G233) -> 0
A234: ='Itens de Contrato'!A234 -> Instalações Hidráulicas - AF Isométricos | B234: ='Itens de Contrato'!B234 -> 3.1.5 | C234: =VLOOKUP(B234,'Itens de Contrato'!B$6:J$873,2,0) -> JOELHO 90o PVC SOLDÁVEL, P/TUBO Ф 32mm, FAB.TIGRE, AMANCO | D234: 2 | E234: =D234*('Itens de Contrato'!F234 + 'Itens de Contrato'!G234) -> 13.748667 | F234: ='Itens de Contrato'!E234 -> 26 | H234: =G234/D234 -> 0 | I234: =G234*('Itens de Contrato'!F234+'Itens de Contrato'!G234) -> 0
A235: ='Itens de Contrato'!A235 -> Instalações Hidráulicas - AF Isométricos | B235: ='Itens de Contrato'!B235 -> 3.1.6 | C235: =VLOOKUP(B235,'Itens de Contrato'!B$6:J$873,2,0) -> JOELHO 90o PVC SOLDÁVEL, C/BUCHA DE LATÃO Ф 25x1/2", FAB.TIGRE, AMANCO | D235: 28 | E235: =D235*('Itens de Contrato'!F235 + 'Itens de Contrato'!G235) -> 373.22602 | F235: ='Itens de Contrato'!E235 -> 391 | H235: =G235/D235 -> 0 | I235: =G235*('Itens de Contrato'!F235+'Itens de Contrato'!G235) -> 0
A236: ='Itens de Contrato'!A236 -> Instalações Hidráulicas - AF Isométricos | B236: ='Itens de Contrato'!B236 -> 3.1.7 | C236: =VLOOKUP(B236,'Itens de Contrato'!B$6:J$873,2,0) -> JOELHO 90o PVC SOLDÁVEL, C/BUCHA DE LATÃO Ф 25x3/4", FAB.TIGRE, AMANCO | D236: 6 | E236: =D236*('Itens de Contrato'!F236 + 'Itens de Contrato'!G236) -> 156.76834 | F236: ='Itens de Contrato'!E236 -> 78 | H236: =G236/D236 -> 0 | I236: =G236*('Itens de Contrato'!F236+'Itens de Contrato'!G236) -> 0
A237: ='Itens de Contrato'!A237 -> Instalações Hidráulicas - AF Isométricos | B237: ='Itens de Contrato'!B237 -> 3.1.8 | C237: =VLOOKUP(B237,'Itens de Contrato'!B$6:J$873,2,0) -> TE 90o PVC SOLDÁVEL, C/BUCHA DE LATÃO Ф 25x1/2", FAB.TIGRE, AMANCO | D237: 12 | E237: =D237*('Itens de Contrato'!F237 + 'Itens de Contrato'!G237) -> 256.27516 | F237: ='Itens de Contrato'!E237 -> 160 | H237: =G237/D237 -> 0 | I237: =G237*('Itens de Contrato'!F237+'Itens de Contrato'!G237) -> 0
A238: ='Itens de Contrato'!A238 -> Instalações Hidráulicas - AF Isométricos | B238: ='Itens de Contrato'!B238 -> 3.1.9 | C238: =VLOOKUP(B238,'Itens de Contrato'!B$6:J$873,2,0) -> TE 90o PVC SOLDÁVEL, C/BUCHA DE LATÃO Ф 25x3/4", FAB.TIGRE, AMANCO | D238: 6 | E238: =D238*('Itens de Contrato'!F238 + 'Itens de Contrato'!G238) -> 237.57697 | F238: ='Itens de Contrato'!E238 -> 78 | H238: =G238/D238 -> 0 | I238: =G238*('Itens de Contrato'!F238+'Itens de Contrato'!G238) -> 0
A239: ='Itens de Contrato'!A239 -> Instalações Hidráulicas - AF Isométricos | B239: ='Itens de Contrato'!B239 -> 3.1.10 | C239: =VLOOKUP(B239,'Itens de Contrato'!B$6:J$873,2,0) -> TE 90o PVC SOLDÁVEL, P/TUBO Ф 25mm, FAB.TIGRE, AMANCO | D239: 14 | E239: =D239*('Itens de Contrato'!F239 + 'Itens de Contrato'!G239) -> 52.032558 | F239: ='Itens de Contrato'!E239 -> 193 | H239: =G239/D239 -> 0 | I239: =G239*('Itens de Contrato'!F239+'Itens de Contrato'!G239) -> 0
A240: ='Itens de Contrato'!A240 -> Instalações Hidráulicas - AF Isométricos | B240: ='Itens de Contrato'!B240 -> 3.1.11 | C240: =VLOOKUP(B240,'Itens de Contrato'!B$6:J$873,2,0) -> TE DE REDUÇÃO 90o PVC SOLDÁVEL, Ф 32x25mm, FAB.TIGRE, AMANCO | D240: 2 | E240: =D240*('Itens de Contrato'!F240 + 'Itens de Contrato'!G240) -> 49.797003 | F240: ='Itens de Contrato'!E240 -> 26 | H240: =G240/D240 -> 0 | I240: =G240*('Itens de Contrato'!F240+'Itens de Contrato'!G240) -> 0
A241: ='Itens de Contrato'!A241 -> Instalações Hidráulicas - AF Isométricos | B241: ='Itens de Contrato'!B241 -> 3.1.12 | C241: =VLOOKUP(B241,'Itens de Contrato'!B$6:J$873,2,0) -> BUCHA DE REDUÇÃO PVC SOLDÁVEL CURTA, Ф 32x25mm, FAB.TIGRE, AMANCO | D241: 2 | E241: =D241*('Itens de Contrato'!F241 + 'Itens de Contrato'!G241) -> 29.621113 | F241: ='Itens de Contrato'!E241 -> 26 | H241: =G241/D241 -> 0 | I241: =G241*('Itens de Contrato'!F241+'Itens de Contrato'!G241) -> 0
A242: ='Itens de Contrato'!A242 -> Instalações Hidráulicas - AF Isométricos | B242: ='Itens de Contrato'!B242 -> 3.1.13 | C242: =VLOOKUP(B242,'Itens de Contrato'!B$6:J$873,2,0) -> ADAPTADOR PVC SOLDÁVEL CURTO P/REGISTRO, Ф 25x3/4", FAB.TIGRE, AMANCO | D242: 34 | E242: =D242*('Itens de Contrato'!F242 + 'Itens de Contrato'!G242) -> 76.008893 | F242: ='Itens de Contrato'!E242 -> 471 | H242: =G242/D242 -> 0 | I242: =G242*('Itens de Contrato'!F242+'Itens de Contrato'!G242) -> 0
... A262: ='Itens de Contrato'!A262 -> Instalações Hidráulicas - AQ Isométricos | B262: ='Itens de Contrato'!B262 -> 3.2.14 | C262: =VLOOKUP(B262,'Itens de Contrato'!B$6:J$873,2,0) -> BASE REGISTRO DE GAVETA ROSCA Ф1", REF. 4509.302, FAB. DECA | D262: 2 | E262: =D262*('Itens de Contrato'!F262 + 'Itens de Contrato'!G262) -> 357.13002 | F262: ='Itens de Contrato'!E262 -> 26 | H262: =G262/D262 -> 0 | I262: =G262*('Itens de Contrato'!F262+'Itens de Contrato'!G262) -> 0
A263: ='Itens de Contrato'!A263 -> Instalações Hidráulicas - AF Prumadas e Distribuição | B263: ='Itens de Contrato'!B263 -> 3.3.1 | C263: =VLOOKUP(B263,'Itens de Contrato'!B$6:J$873,2,0) -> TUBO CPVC SOLDÁVEL PN 20, LINHA PREDIAL, NBR-15884-2, Ф 42mm x 3,0m, FAB. TIGRE, AMANCO | D263: ='Itens de Contrato'!E263 -> 11 | E263: =D263*('Itens de Contrato'!F263 + 'Itens de Contrato'!G263) -> 4582.8089 | F263: ='Itens de Contrato'!E263 -> 11 | H263: =G263/D263 -> 0 | I263: =G263*('Itens de Contrato'!F263+'Itens de Contrato'!G263) -> 0
A264: ='Itens de Contrato'!A264 -> Instalações Hidráulicas - AF Prumadas e Distribuição | B264: ='Itens de Contrato'!B264 -> 3.3.2 | C264: =VLOOKUP(B264,'Itens de Contrato'!B$6:J$873,2,0) -> TUBO CPVC SOLDÁVEL PN 20, LINHA PREDIAL, NBR-15884-2, Ф 54mm x 3,0m, FAB. TIGRE, AMANCO | D264: ='Itens de Contrato'!E264 -> 59 | E264: =D264*('Itens de Contrato'!F264 + 'Itens de Contrato'!G264) -> 44117.448 | F264: ='Itens de Contrato'!E264 -> 59 | H264: =G264/D264 -> 0 | I264: =G264*('Itens de Contrato'!F264+'Itens de Contrato'!G264) -> 0
A265: ='Itens de Contrato'!A265 -> Instalações Hidráulicas - AF Prumadas e Distribuição | B265: ='Itens de Contrato'!B265 -> 3.3.3 | C265: =VLOOKUP(B265,'Itens de Contrato'!B$6:J$873,2,0) -> TUBO CPVC SOLDÁVEL PN 20, LINHA PREDIAL, NBR-15884-2, Ф 73mm x 3,0m, FAB. TIGRE, AMANCO | D265: ='Itens de Contrato'!E265 -> 8 | E265: =D265*('Itens de Contrato'!F265 + 'Itens de Contrato'!G265) -> 8837.2768 | F265: ='Itens de Contrato'!E265 -> 8 | H265: =G265/D265 -> 0 | I265: =G265*('Itens de Contrato'!F265+'Itens de Contrato'!G265) -> 0
A266: ='Itens de Contrato'!A266 -> Instalações Hidráulicas - AF Prumadas e Distribuição | B266: ='Itens de Contrato'!B266 -> 3.3.4 | C266: =VLOOKUP(B266,'Itens de Contrato'!B$6:J$873,2,0) -> LUVA SIMPLES FF CPVC SOLDÁVEL, P/TUBO Ф 42mm, FAB.TIGRE, AMANCO | D266: ='Itens de Contrato'!E266 -> 42 | E266: =D266*('Itens de Contrato'!F266 + 'Itens de Contrato'!G266) -> 1571.6102 | F266: ='Itens de Contrato'!E266 -> 42 | H266: =G266/D266 -> 0 | I266: =G266*('Itens de Contrato'!F266+'Itens de Contrato'!G266) -> 0
A267: ='Itens de Contrato'!A267 -> Instalações Hidráulicas - AF Prumadas e Distribuição | B267: ='Itens de Contrato'!B267 -> 3.3.5 | C267: =VLOOKUP(B267,'Itens de Contrato'!B$6:J$873,2,0) -> LUVA SIMPLES FF CPVC SOLDÁVEL, P/TUBO Ф 54mm, FAB.TIGRE, AMANCO | D267: ='Itens de Contrato'!E267 -> 59 | E267: =D267*('Itens de Contrato'!F267 + 'Itens de Contrato'!G267) -> 4449.6806 | F267: ='Itens de Contrato'!E267 -> 59 | H267: =G267/D267 -> 0 | I267: =G267*('Itens de Contrato'!F267+'Itens de Contrato'!G267) -> 0
A268: ='Itens de Contrato'!A268 -> Instalações Hidráulicas - AF Prumadas e Distribuição | B268: ='Itens de Contrato'!B268 -> 3.3.6 | C268: =VLOOKUP(B268,'Itens de Contrato'!B$6:J$873,2,0) -> LUVA SIMPLES FF CPVC SOLDÁVEL, P/TUBO Ф 73mm, FAB.TIGRE, AMANCO | D268: ='Itens de Contrato'!E268 -> 7 | E268: =D268*('Itens de Contrato'!F268 + 'Itens de Contrato'!G268) -> 2981.2633 | F268: ='Itens de Contrato'!E268 -> 7 | H268: =G268/D268 -> 0 | I268: =G268*('Itens de Contrato'!F268+'Itens de Contrato'!G268) -> 0
A269: ='Itens de Contrato'!A269 -> Instalações Hidráulicas - AF Prumadas e Distribuição | B269: ='Itens de Contrato'!B269 -> 3.3.7 | C269: =VLOOKUP(B269,'Itens de Contrato'!B$6:J$873,2,0) -> JOELHO 90o DE TRANSIÇÃO CPVC SOLDÁVEL, P/TUBO Ф 22mm x 3/4", FAB.TIGRE, AMANCO | D269: ='Itens de Contrato'!E269 -> 6 | E269: =D269*('Itens de Contrato'!F269 + 'Itens de Contrato'!G269) -> 415.81336 | F269: ='Itens de Contrato'!E269 -> 6 | H269: =G269/D269 -> 0 | I269: =G269*('Itens de Contrato'!F269+'Itens de Contrato'!G269) -> 0
A270: ='Itens de Contrato'!A270 -> Instalações Hidráulicas - AF Prumadas e Distribuição | B270: ='Itens de Contrato'!B270 -> 3.3.8 | C270: =VLOOKUP(B270,'Itens de Contrato'!B$6:J$873,2,0) -> JOELHO 90o FF CPVC SOLDÁVEL, P/TUBO Ф 42mm, FAB.TIGRE, AMANCO | D270: ='Itens de Contrato'!E270 -> 13 | E270: =D270*('Itens de Contrato'!F270 + 'Itens de Contrato'!G270) -> 877.31588 | F270: ='Itens de Contrato'!E270 -> 13 | H270: =G270/D270 -> 0 | I270: =G270*('Itens de Contrato'!F270+'Itens de Contrato'!G270) -> 0
...

Sheet Medição 02
E1: OBRA | F1: ='Cadastro Institucional'!D$6 -> Condominio Palatium | G1: ='Cadastro Institucional'!D$7 -> 0
A2: CNPJ | B2: Razão Social | C2: Inscrição Estadual | D2: Responsável | E2: Cargo | F2: Telefone | G2: E-mail | H2: Medição Nº | I2: Período
A3: ='Cadastro Institucional'!D$10 -> 23.471.824/0001-45 | B3: ='Cadastro Institucional'!D$9 -> F A Alves Vasoncelos Ltda. | C3: ='Cadastro Institucional'!D$11 -> 0 | D3: ='Cadastro Institucional'!D$12 -> Francisco de Assis Alves Vasocnelos | E3: ='Cadastro Institucional'!D$13 -> Enegenheiro Responsável | F3: ='Cadastro Institucional'!D$14 -> (88) 9 8802-1038 | G3: ='Cadastro Institucional'!D$15 -> spateeng@gmail.com
A5: Etapa | B5: Item | C5: Descrição | D5: Quantidade Contratada | E5: Valor Contratado | F5: Saldo Total à Medir | G5: Quantidade Executada | H5: % Executado | I5: Valor Executado | K5: Preencha apenas as células com esse azul claro como cor de fundo!
A6: ='Itens de Contrato'!A6 -> Instalações Elétricas - Tubulações Laje aparente | B6: ='Itens de Contrato'!B6 -> 1.1.1 | C6: =VLOOKUP(B6,'Itens de Contrato'!B$5:J$151,2,0) -> ELETRODUTO PVC RÍGIDO ROSCÁVEL, CLASSE B, NBR-15465, Ф 3/4" x 3,0m, FAB.TIGRE, AMANCO | D6: =F6 -> 1907 | E6: =D6*('Itens de Contrato'!F6+'Itens de Contrato'!G6) -> 71248.808 | F6: ='Medição 01'!F6-'Medição 01'!G6 -> 1907 | H6: =G6/D6 -> 0 | I6: =G6*('Itens de Contrato'!F6+'Itens de Contrato'!G6) -> 0
A7: ='Itens de Contrato'!A7 -> Instalações Elétricas - Tubulações Laje aparente | B7: ='Itens de Contrato'!B7 -> 1.1.2 | C7: =VLOOKUP(B7,'Itens de Contrato'!B$5:J$151,2,0) -> ELETRODUTO PVC RÍGIDO ROSCÁVEL, CLASSE B, NBR-15465, Ф 1" x 3,0m, FAB.TIGRE, AMANCO | D7: =F7 -> 31 | E7: =D7*('Itens de Contrato'!F7+'Itens de Contrato'!G7) -> 1846.038 | F7: ='Medição 01'!F7-'Medição 01'!G7 -> 31 | H7: =G7/D7 -> 0 | I7: =G7*('Itens de Contrato'!F7+'Itens de Contrato'!G7) -> 0
A8: ='Itens de Contrato'!A8 -> Instalações Elétricas - Tubulações Laje aparente | B8: ='Itens de Contrato'!B8 -> 1.1.3 | C8: =VLOOKUP(B8,'Itens de Contrato'!B$5:J$151,2,0) -> CURVA 90o P/ELETRODUTO PVC RÍGIDO, ROSCA Ф 3/4", FAB.TIGRE, AMANCO | D8: =F8 -> 1653 | E8: =D8*('Itens de Contrato'!F8+'Itens de Contrato'!G8) -> 13996.227 | F8: ='Medição 01'!F8-'Medição 01'!G8 -> 1653 | H8: =G8/D8 -> 0 | I8: =G8*('Itens de Contrato'!F8+'Itens de Contrato'!G8) -> 0
A9: ='Itens de Contrato'!A9 -> Instalações Elétricas - Tubulações Laje aparente | B9: ='Itens de Contrato'!B9 -> 1.1.4 | C9: =VLOOKUP(B9,'Itens de Contrato'!B$5:J$151,2,0) -> CURVA 90o P/ELETRODUTO PVC RÍGIDO, ROSCA Ф 1", FAB.TIGRE, AMANCO | D9: =F9 -> 3 | E9: =D9*('Itens de Contrato'!F9+'Itens de Contrato'!G9) -> 36.216002 | F9: ='Medição 01'!F9-'Medição 01'!G9 -> 3 | H9: =G9/D9 -> 0 | I9: =G9*('Itens de Contrato'!F9+'Itens de Contrato'!G9) -> 0
A10: ='Itens de Contrato'!A10 -> Instalações Elétricas - Tubulações Laje aparente | B10: ='Itens de Contrato'!B10 -> 1.1.5 | C10: =VLOOKUP(B10,'Itens de Contrato'!B$5:J$151,2,0) -> LUVA P/ELETRODUTO PVC RÍGIDO, ROSCA Ф 3/4", FAB.TIGRE, AMANCO | D10: =F10 -> 3560 | E10: =D10*('Itens de Contrato'!F10+'Itens de Contrato'!G10) -> 16016.639 | F10: ='Medição 01'!F10-'Medição 01'!G10 -> 3560 | H10: =G10/D10 -> 0 | I10: =G10*('Itens de Contrato'!F10+'Itens de Contrato'!G10) -> 0
A11: ='Itens de Contrato'!A11 -> Instalações Elétricas - Tubulações Laje aparente | B11: ='Itens de Contrato'!B11 -> 1.1.6 | C11: =VLOOKUP(B11,'Itens de Contrato'!B$5:J$151,2,0) -> LUVA P/ELETRODUTO PVC RÍGIDO, ROSCA Ф 1", FAB.TIGRE, AMANCO | D11: =F11 -> 34 | E11: =D11*('Itens de Contrato'!F11+'Itens de Contrato'!G11) -> 246.07879 | F11: ='Medição 01'!F11-'Medição 01'!G11 -> 34 | H11: =G11/D11 -> 0 | I11: =G11*('Itens de Contrato'!F11+'Itens de Contrato'!G11) -> 0
A12: ='Itens de Contrato'!A12 -> Instalações Elétricas - Tubulações Laje aparente | B12: ='Itens de Contrato'!B12 -> 1.1.7 | C12: =VLOOKUP(B12,'Itens de Contrato'!B$5:J$151,2,0) -> BUCHA E ARRUELA EM LIGA DE ALUMINIO SILÍCIO Ф 3/4", FAB. WETZEL, TRAMONTINA | D12: =F12 -> 2914 | E12: =D12*('Itens de Contrato'!F12+'Itens de Contrato'!G12) -> 17751.765 | F12: ='Medição 01'!F12-'Medição 01'!G12 -> 2914 | H12: =G12/D12 -> 0 | I12: =G12*('Itens de Contrato'!F12+'Itens de Contrato'!G12) -> 0
A13: ='Itens de Contrato'!A13 -> Instalações Elétricas - Tubulações Laje aparente | B13: ='Itens de Contrato'!B13 -> 1.1.8 | C13: =VLOOKUP(B13,'Itens de Contrato'!B$5:J$151,2,0) -> ARAME GALVANIZADO BITOLA 16BWG - GERDAU | D13: =F13 -> 55 | E13: =D13*('Itens de Contrato'!F13+'Itens de Contrato'!G13) -> 3980.6863 | F13: ='Medição 01'!F13-'Medição 01'!G13 -> 55 | H13: =G13/D13 -> 0 | I13: =G13*('Itens de Contrato'!F13+'Itens de Contrato'!G13) -> 0
A14: ='Itens de Contrato'!A14 -> Instalações Elétricas - Tubulações Laje aparente | B14: ='Itens de Contrato'!B14 -> 1.1.9 | C14: =VLOOKUP(B14,'Itens de Contrato'!B$5:J$151,2,0) -> PARAFUSO FENDA, ROSCA SOBERBA C/BUCHA DE NYLON Ref. S8 x 40mm, FAB. MAXTIL,CARMEHIL | D14: =F14 -> 3829 | E14: =D14*('Itens de Contrato'!F14+'Itens de Contrato'!G14) -> 9308.9377 | F14: ='Medição 01'!F14-'Medição 01'!G14 -> 3829 | H14: =G14/D14 -> 0 | I14: =G14*('Itens de Contrato'!F14+'Itens de Contrato'!G14) -> 0
A15: ='Itens de Contrato'!A15 -> Instalações Elétricas - Tubulações Laje aparente | B15: ='Itens de Contrato'!B15 -> 1.1.10 | C15: =VLOOKUP(B15,'Itens de Contrato'!B$5:J$151,2,0) -> ABRAÇADEIRA AÇO GALVANIZADO, TIPO "D" C/CUNHA Ф 3/4", Ref. MAX.AA.TDC, FAB. MAXTIL,CARMEHIL | D15: =F15 -> 2922 | E15: =D15*('Itens de Contrato'!F15+'Itens de Contrato'!G15) -> 6777.2547 | F15: ='Medição 01'!F15-'Medição 01'!G15 -> 2922 | H15: =G15/D15 -> 0 | I15: =G15*('Itens de Contrato'!F15+'Itens de Contrato'!G15) -> 0
A16: ='Itens de Contrato'!A16 -> Instalações Elétricas - Tubulações Laje aparente | B16: ='Itens de Contrato'!B16 -> 1.1.11 | C16: =VLOOKUP(B16,'Itens de Contrato'!B$5:J$151,2,0) -> CONDULETE MÚLTIPLO EM LIGA DE ALUMÍNIO, PARAF. AÇO ZINCADO, TAMPA E JUNTA DE VEDAÇÃO, ROSCA Ф 3/4", FAB. WETZEL | D16: =F16 -> 68 | E16: =D16*('Itens de Contrato'!F16+'Itens de Contrato'!G16) -> 2650.8101 | F16: ='Medição 01'!F16-'Medição 01'!G16 -> 68 | H16: =G16/D16 -> 0 | I16: =G16*('Itens de Contrato'!F16+'Itens de Contrato'!G16) -> 0
A17: ='Itens de Contrato'!A17 -> Instalações Elétricas - Tubulações Laje aparente | B17: ='Itens de Contrato'!B17 -> 1.1.12 | C17: =VLOOKUP(B17,'Itens de Contrato'!B$5:J$151,2,0) -> CONECTOR EM ALUM.SILICIO P/CONDULETE MÚLTIPLO, PARAF. AÇO ZINCADO, ROSCA EXTERNA Ф 3/4", FAB. WETZEL | D17: =F17 -> 204 | E17: =D17*('Itens de Contrato'!F17+'Itens de Contrato'!G17) -> 666.97804 | F17: ='Medição 01'!F17-'Medição 01'!G17 -> 204 | H17: =G17/D17 -> 0 | I17: =G17*('Itens de Contrato'!F17+'Itens de Contrato'!G17) -> 0
... A151: ='Itens de Contrato'!A151 -> Instalações Elétricas - Quadros - Cabeamento | B151: ='Itens de Contrato'!B151 -> 1.8.21 | C151: =VLOOKUP(B151,'Itens de Contrato'!B$5:J$151,2,0) -> ANILHAS / MARCADORES, FAB. HELLERMANN, PIAL | D151: =F151 -> 1200 | E151: =D151*('Itens de Contrato'!F151+'Itens de Contrato'!G151) -> 838.33338 | F151: ='Medição 01'!F151-'Medição 01'!G151 -> 1200 | H151: =G151/D151 -> 0 | I151: =G151*('Itens de Contrato'!F151+'Itens de Contrato'!G151) -> 0

Sheet Medição 03
E1: OBRA | F1: ='Cadastro Institucional'!D$6 -> Condominio Palatium | G1: ='Cadastro Institucional'!D$7 -> 0
A2: CNPJ | B2: Razão Social | C2: Inscrição Estadual | D2: Responsável | E2: Cargo | F2: Telefone | G2: E-mail | H2: Medição Nº | I2: Período
A3: ='Cadastro Institucional'!D$10 -> 23.471.824/0001-45 | B3: ='Cadastro Institucional'!D$9 -> F A Alves Vasoncelos Ltda. | C3: ='Cadastro Institucional'!D$11 -> 0 | D3: ='Cadastro Institucional'!D$12 -> Francisco de Assis Alves Vasocnelos | E3: ='Cadastro Institucional'!D$13 -> Enegenheiro Responsável | F3: ='Cadastro Institucional'!D$14 -> (88) 9 8802-1038 | G3: ='Cadastro Institucional'!D$15 -> spateeng@gmail.com
A5: Etapa | B5: Item | C5: Descrição | D5: Quantidade Contratada | E5: Valor Contratado | F5: Saldo Total à Medir | G5: Quantidade Executada | H5: % Executado | I5: Valor Executado | K5: Preencha apenas as células com esse azul claro como cor de fundo!
A6: ='Itens de Contrato'!A6 -> Instalações Elétricas - Tubulações Laje aparente | B6: ='Itens de Contrato'!B6 -> 1.1.1 | C6: =VLOOKUP(B6,'Itens de Contrato'!B$5:J$151,2,0) -> ELETRODUTO PVC RÍGIDO ROSCÁVEL, CLASSE B, NBR-15465, Ф 3/4" x 3,0m, FAB.TIGRE, AMANCO | D6: ='Itens de Contrato'!E6 -> 1907 | E6: =D6*('Itens de Contrato'!F6+'Itens de Contrato'!G6) -> 71248.808 | F6: ='Medição 02'!F6-'Medição 02'!G6 -> 1907 | H6: =G6/D6 -> 0 | I6: =G6*('Itens de Contrato'!F6+'Itens de Contrato'!G6) -> 0
A7: ='Itens de Contrato'!A7 -> Instalações Elétricas - Tubulações Laje aparente | B7: ='Itens de Contrato'!B7 -> 1.1.2 | C7: =VLOOKUP(B7,'Itens de Contrato'!B$5:J$151,2,0) -> ELETRODUTO PVC RÍGIDO ROSCÁVEL, CLASSE B, NBR-15465, Ф 1" x 3,0m, FAB.TIGRE, AMANCO | D7: ='Itens de Contrato'!E7 -> 31 | E7: =D7*('Itens de Contrato'!F7+'Itens de Contrato'!G7) -> 1846.038 | F7: ='Medição 02'!F7-'Medição 02'!G7 -> 31 | H7: =G7/D7 -> 0 | I7: =G7*('Itens de Contrato'!F7+'Itens de Contrato'!G7) -> 0
